Workbook
Name total_reducido: 'Study selection'!$A$1:$BB$135

Sheet Study selection
B1: authors | C1: author full names | D1: author(s) id | E1: title | F1: year | G1: source title | H1: volume | I1: issue | J1: art. no. | K1: page start | L1: page end | M1: page count | N1: cited by | O1: doi | P1: link | Q1: affiliations | R1: authors with affiliations | S1: abstract | T1: author keywords | U1: index keywords | V1: molecular sequence numbers | W1: chemicals/cas | X1: tradenames | Y1: manufacturers | Z1: funding details | AA1: funding texts | AB1: references | AC1: correspondence address | AD1: editors | AE1: publisher | AF1: sponsors | AG1: conference name | AH1: conference date | AI1: conference location | AJ1: conference code | AK1: issn | AL1: isbn | AM1: coden | AN1: pubmed id | AO1: language of original document | AP1: abbreviated source title | AQ1: document type | AR1: publication stage | AS1: open access | AT1: source | AU1: eid | AV1: query | AW1: search_engine | AX1: peer_review_conference | AY1: peer_review_color | AZ1: peer_review_publisher | BA1: peer_review_color | BB1: peer_review_abbreviation | BC1: peer_review_color | BD1: title | BE1: abstract | BF1: full text | BG1: choosen | BH1: choosen_state | BI1: downloaded | BJ1: done | BK1: notes
A2: 154 | B2: Chen J.; Verspoor K.; Zhai Z. | C2: Chen, Jiyu (57216991109); Verspoor, Karin (12772581800); Zhai, Zenan (57216645849) | D2: 57216991109; 12772581800; 57216645849 | E2: A bag-of-concepts model improves relation extraction in a narrow knowledge domain with limited data | F2: 2019.0 | G2: NAACL HLT 2019 - 2019 Conference of the North American Chapter of the Association for Computational Linguistics: Human Language Technologies - Proceedings of the Student Research Workshop | K2: 43.0 | L2: 52.0 | M2: 9.0 | N2: 2.0 | P2: https://www.scopus.com/inward/record.uri?eid=2-s2.0-85085638027&partnerID=40&md5=b29a1a9e22b0c9dc26388717597a8950 | Q2: School of Computing and Information Systems, University of Melbourne, Australia | R2: Chen J., School of Computing and Information Systems, University of Melbourne, Australia; Verspoor K., School of Computing and Information Systems, University of Melbourne, Australia; Zhai Z., School of Computing and Information Systems, University of Melbourne, Australia | S2: This paper focuses on a traditional relation extraction task in the context of limited annotated data and a narrow knowledge domain. We explore this task with a clinical corpus consisting of 200 breast cancer follow-up treatment letters in which 16 distinct types of relations are annotated. We experiment with an approach to extracting typed relations called windowbounded co-occurrence (WBC), which uses an adjustable context window around entity mentions of a relevant type, and compare its performance with a more typical intra-sentential co-occurrence baseline. We further introduce a new bag-of-concepts (BoC) approach to feature engineering based on the state-of-the-art word embeddings and word synonyms. We demonstrate the competitiveness of BoC by comparing with methods of higher complexity, and explore its effectiveness on this small dataset. ¬© 2017 Association for Computational Linguistics. | U2: Computational linguistics; Extraction; Breast Cancer; Co-occurrence; Context window; Feature engineerings; Knowledge domains; Relation extraction; State of the art; Types of relations; Data mining | AB2: Ben Abacha A., Zweigenbaum P., Automatic extraction of semantic relations between medical entities: A rule based approach, Journal of Biomedical Semantics, 2, 5, (2011); Ammar W., Peters M., Bhagavatula C., Power R., The AI2 system at SemEval-2017 Task 10 (ScienceIE): Semisupervised end-to-end entity and relation extraction, Proceedings of the 11th International Workshop on Semantic Evaluation (SemEval-2017), pp. 592-596, (2017); Aronson A.R., Effective mapping of biomedical text to the UMLS Metathesaurus: The MetaMap program, Proceedings of the AMIA Symposium, (2001); Bird S., Klein E., Loper E., Natural Language Processing with Python: Analyzing Text with the Natural Language Toolkit, (2009); Brown P.F., Desouza P.V., Mercer R.L., Pietra Della V.J., Lai J.C., Class-based n-gram models of natural language, Computational Linguistics, 18, 4, pp. 467-479, (1992); Chaix E., Dubreucq B., Fatihi A., Valsamou D., Bossy R., Ba M., Deleger L., Zweigenbaum P., Bessieres P., Lepiniec L., Et al., Overview of the Regulatory Network of Plant Seed Development (SeeDev) Task at the BioNLP Shared Task 2016, Proceedings of the 4th BioNLP Shared Task Workshop, pp. 1-11, (2016); Chollet F., Et al., Keras, (2015); Fundel K., Kuffner R., Zimmer R., RelExRelation extraction using dependency parse trees, Bioinformatics, 23, 3, pp. 365-371, (2006); Funk C., Baumgartner W., Garcia B., Roeder C., Bada M., Cohen K., Hunter L., Verspoor K., Largescale biomedical concept recognition: An evaluation of current automatic annotators and their parameters, BMC Bioinformatics, 15, 1, (2014); Hagberg A., Swart P., Chult D.S., Exploring Network Structure, Dynamics, and Function Using NetworkX, (2008); Hearst M.A., Support Vector Machines, IEEE Intelligent Systems, 13, 4, pp. 18-28, (1998); Yao Huang Y., Yang Wang W., Deep Residual Learning for Weakly-Supervised Relation Extraction, Proceedings of the 2017 Conference on Empirical Methods in Natural Language Processing, EMNLP 2017, pp. 1803-1807, (2017); Li J., Sun Y., Johnson R.J., Sciaky D., Wei C., Leaman R., Peter Davis A., Mattingly C.J., Wiegers T., Lu Z., Biocreative v Cdr Task Corpus: A Resource for Chemical Disease Relation Extraction, (2016); Liu H., Hunter L., Keselj V., Verspoor K., Approximate subgraph matchingbased literature mining for biomedical events and relations, PloS One, 8, 4, (2013); Manning C., Surdeanu M., Bauer J., Finkel J., Bethard S., McClosky D., The Stanford CoreNLP natural language processing toolkit, Proceedings of 52nd Annual Meeting of the Association for Computational Linguistics: System Demonstrations, pp. 55-60, (2014); Mikolov T., Chen K., Corrado G., Dean J., Efficient estimation of word representations in vector space, CoRR, (2013); Mikolov T., Sutskever I., Chen K., Corrado G.S., Dean J., Distributed representations of words and phrases and their compositionality, Advances in Neural Information Processing Systems, pp. 3111-3119, (2013); Moen S., Salakoski T., Sophia A., Distributional semantics resources for biomedical text processing, Proceedings of the 5th International Symposium on Languages in Biology and Medicine, pp. 39-43, (2013); Quoc Nguyen D., Verspoor K., Convolutional neural networks for chemical-disease relation extraction are improved with character-based word embeddings, Proceedings of the BioNLP 2018 Workshop, pp. 129-136, (2018); Huu Nguyen T., Grishman R., Combining Neural Networks and Log-linear Models to Improve Relation Extraction, Proceedings of IJCAI Workshop on Deep Learning for Artificial Intelligence (DLAI), (2016); Panyam N.C., Verspoor K., Cohn T., Kotagiri R., ASM Kernel: Graph Kernel using Approximate Subgraph Matching for Relation Extraction, Proceedings of the Australasian Language Technology Association Workshop 2016, pp. 65-73, (2016); Pedregosa F., Varoquaux G., Gramfort A., Michel V., Thirion B., Grisel O., Blondel M., Prettenhofer P., Weiss R., Dubourg V., Vanderplas J., Passos A., Cournapeau D., Brucher M., Perrot M., Duchesnay E., Scikit-learn: Machine learning in Python, Journal of Machine Learning Research, 12, pp. 2825-2830, (2011); Peng N., Poon H., Quirk C., Toutanova K., Yih W., Cross-Sentence N-ary Relation Extraction with Graph LSTMs, Transactions of the Association of Computational Linguistics, 5, 1, pp. 101-115, (2017); Pennington J., Socher R., Manning C., Glove: Global vectors for word representation, Proceedings of the 2014 Conference on Empirical Methods in Natural Language Processing (EMNLP), pp. 1532-1543, (2014); Pitson G., Banks P., Cavedon L., Verspoor K., Developing a Manually Annotated Corpus of Clinical Letters for Breast Cancer Patients on Routine Follow-Up, Studies in Health Technology and Informatics, 235, pp. 196-200, (2017); Rehurek R., Sojka P., Software framework for topic modelling with large corpora, Proceedings of the LREC 2010 Workshop on New Challenges for NLP Frameworks, (2010); Sahlgren M., Coster R., Using bag-of-concepts to improve the performance of support vector machines in text categorization, Proceedings of the 20th International Conference on Computational Linguistics, (2004); Song M., Chul Kim W., Lee D., Eun Heo G., Young Kang K., PKDE4J: Entity and relation extraction for public knowledge discovery, Journal of Biomedical Informatics, 57, pp. 320-332, (2015); Turian J., Ratinov L., Bengio Y., Word representations: A simple and general method for semi-supervised learning, Proceedings of the 48th Annual Meeting of the Association for Computational Linguistics, pp. 384-394, (2010); Verspoor K., Jimeno Yepes A., Cavedon L., McIntosh T., Herten-Crabb A., Thomas Z., Plazzer J., Annotating the biomedical literature for the human variome, Database 2013, (2013); Verspoor K.M., Eun Heo G., Young Kang K., Song M., Establishing a baseline for literature mining human genetic variants and their relationships to disease cohorts, BMC Medical Informatics and Decision Making, 16, 1, (2016); Wei C., Peng Y., Leaman R., Peter Davis A., Mattingly C.J., Li J., Wiegers T.C., Lu Z., Overview of the BioCreative V chemical disease relation (CDR) task, Proceedings of the Fifth BioCreative Challenge Evaluation Workshop, pp. 154-166, (2015) | AC2: J. Chen; School of Computing and Information Systems, University of Melbourne, Australia; email: jiyuc@student.unimelb.edu.au | AE2: Association for Computational Linguistics (ACL) | AG2: 2019 Conference of the North American Chapter of the Association for Computational Linguistics: Human Language Technologies, NAACL HLT 2019 - Student Research Workshop, SRW 2019 | AH2: 3 June 2019 through 5 June 2019 | AI2: Minneapolis | AJ2: 159853.0 | AL2: 978-195073715-4 | AO2: English | AP2: NAACL HLT - Conf. N. Am. Chapter Assoc. Comput. Linguistics: Hum. Lang. Technol. - Proc. Stud. Res. Workshop | AQ2: Conference paper | AR2: Final | AT2: Scopus | AU2: 2-s2.0-85085638027 | AV2: q3 | AW2: Scopus | AX2: TRUE | AY2: =IF(AX2=TRUE,1,IF(AX2=FALSE,0,-1)) -> 1 | AZ2: TRUE | BA2: =IF(AZ2=TRUE,1,IF(AZ2=FALSE,0,-1)) -> 1 | BB2: TRUE | BC2: =IF(BB2=TRUE,1,IF(BB2=FALSE,0,-1)) -> 1 | BD2: 1 | BE2: 1 | BF2: 0 | BG2: 0 | BH2: =IF(BG2=1,"Yes",IF(BG2=-1,"Doubt","No")) -> No | BI2: =IF(BF2=1,"Yes","No") -> No | BJ2: 0 | BK2: It is focused on biomedical domain. It talks about improve relation classsification by a Bag-of-concepts and context.
A3: 52 | B3: Zhao X.; Deng Y.; Yang M.; Wang L.; Zhang R.; Cheng H.; Lam W.; Shen Y.; Xu R. | C3: Zhao, Xiaoyan (57218707688); Deng, Yang (57200607347); Yang, Min (56349712700); Wang, Lingzhi (57216694549); Zhang, Rui (54947068500); Cheng, Hong (7404284983); Lam, Wai (57203073460); Shen, Ying (56763084800); Xu, Ruifeng (56048299800) | D3: 57218707688; 57200607347; 56349712700; 57216694549; 54947068500; 7404284983; 57203073460; 56763084800; 56048299800 | E3: A Comprehensive Survey on Relation Extraction: Recent Advances and New Frontiers | F3: 2024.0 | G3: ACM Computing Surveys | H3: 56 | I3: 11.0 | J3: 293 | N3: 7.0 | O3: 10.1145/3674501 | P3: https://www.scopus.com/inward/record.uri?eid=2-s2.0-85200560529&doi=10.1145%2f3674501&partnerID=40&md5=7f8fd6f9a70dcf2e17d9ffb2ebc9559e | Q3: The Chinese University of Hong Kong, Hong Kong, Hong Kong; Singapore Management University, Singapore, Singapore; Shenzhen Institutes of Advanced Technology, Chinese Academy of Sciences, Guangdong, Shenzhen, China; Huazhong University of Science and Technology, Wuhan, China; Sun Yat-Sen University, Guangdong, Shenzhen, China; Harbin Institute of Technology Shenzhen, GuanDong, Shenzhen, China | R3: Zhao X., The Chinese University of Hong Kong, Hong Kong, Hong Kong; Deng Y., Singapore Management University, Singapore, Singapore; Yang M., Shenzhen Institutes of Advanced Technology, Chinese Academy of Sciences, Guangdong, Shenzhen, China; Wang L., The Chinese University of Hong Kong, Hong Kong, Hong Kong; Zhang R., Huazhong University of Science and Technology, Wuhan, China; Cheng H., The Chinese University of Hong Kong, Hong Kong, Hong Kong; Lam W., The Chinese University of Hong Kong, Hong Kong, Hong Kong; Shen Y., Sun Yat-Sen University, Guangdong, Shenzhen, China; Xu R., Harbin Institute of Technology Shenzhen, GuanDong, Shenzhen, China | S3: Relation extraction (RE) involves identifying the relations between entities from underlying content. RE serves as the foundation for many natural language processing (NLP) and information retrieval applications, such as knowledge graph completion and question answering. In recent years, deep neural networks have dominated the field of RE and made noticeable progress. Subsequently, the large pre-trained language models (PLMs) have taken the state-of-the-art RE to a new level. This survey provides a comprehensive review of existing deep learning techniques for RE. First, we introduce RE resources, including datasets and evaluation metrics. Second, we propose a new taxonomy to categorize existing works from three perspectives, i.e., text representation, context encoding, and triplet prediction. Third, we discuss several important challenges faced by RE and summarize potential techniques to tackle these challenges. Finally, we outline some promising future directions and prospects in this field. This survey is expected to facilitate researchers‚Äô collaborative efforts to address the challenges of real-world RE systems. ¬© 2024 Copyright held by the owner/author(s). Publication rights licensed to ACM. | T3: deep learning; low-resource relation extraction; pre-trained language models; Relation extraction | U3: Computational linguistics; Extraction; Knowledge graph; Learning systems; Natural language processing systems; Deep learning; Language informations; Language model; Language processing; Low-resource relation extraction; Natural languages; Pre-trained language model; Relation extraction; Retrieval applications; Deep neural networks | Z3: Research Grants Council, University Grants Committee, Á†îÁ©∂Ë≥áÂä©Â±Ä, (CUHK 14217622); Shenzhen Basic Research Foundation, (JCYJ20210324115614039); Shenzhen Science and Technology Innovation Program, (KQTD20190929172835662); National Natural Science Foundation of China, NSFC, (62376262); Natural Science Foundation of Guangdong Province, (2024A1515030166); National Key Research and Development Program of China, NKRDPC, (2022YFF0902100) | AA3: This research is supported in part by grants from the Research Grant Council of the Hong Kong Special Administrative Region, China (No. CUHK 14217622). Min Yang was supported by National Key Research and Development Program of China (2022YFF0902100), National Natural Science Foundation of China (62376262), the Natural Science Foundation of Guangdong Province of China (2024A1515030166), Shenzhen Science and Technology Innovation Program (KQTD20190929172835662), Shenzhen Basic Research Foundation (JCYJ20210324115614039). | AB3: Achiam J., Adler S., Agarwal S., Ahmad L., Akkaya I., Aleman F.L., Almeida D., Altenschmidt J., Altman S., Anadkat S., Gpt-4 technical report, (2023); Agrawal M., Hegselmann S., Lang H., Kim Y., Sontag D., Large language models are few-shot clinical information extractors, Proceedings of the 2022 Conference on Empirical Methods in Natural Language Processing, pp. 1998-2022, (2022); Ahmed M., Islam J., Samee M.R., Mercer R.E., Identifying protein-protein interaction using tree LSTM and structured attention, Proceedings of the 2019 IEEE 13th International Conference on Semantic Computing (ICSC), pp. 224-231, (2019); Albalak A., Embar V., Tuan Y.-L., Getoor L., Wang W.Y., D-REX: Dialogue relation extraction with explanations, Proceedings of the 4th Workshop on NLP for Conversational AI, pp. 34-46, (2022); Andrew J.J., Automatic extraction of entities and relation from legal documents, Proceedings of the 7th Named Entities Workshop, pp. 1-8, (2018); Andrew J.J., Automatic extraction of entities and relation from legal documents, Proceedings of the NEWS@ACL, (2018); Asada M., Integrating heterogeneous domain information into relation extraction: A case study on drug-drug interaction extraction, (2022); Augenstein I., Das M., Riedel S., Vikraman L., McCallum A., SemEval 2017 Task 10: ScienceIE - extracting keyphrases and relations from scientific publications, Proceedings of the International Workshop on Semantic Evaluation, (2017); Pawar S., Palshikar G.K., Bhattacharyya P., Relation extraction: A survey, (2017); Bassignana E., Plank B., What do you mean by relation extraction? a survey on datasets and study on scientific relation classification, Proceedings of the Annual Meeting of the Association for Computational Linguistics, (2022); Beltagy I., Lo K., Cohan A., SciBERT: A pretrained language model for scientific text, Proceedings of the 2019 Conference on Empirical Methods in Natural Language Processing and the 9th International Joint Conference on Natural Language Processing (EMNLP-IJCNLP), pp. 3615-3620, (2019); Bhartiya A., Badola K., Mausam, DiS-ReX: A multilingual dataset for distantly supervised relation extraction, Proceedings of the Annual Meeting of the Association for Computational Linguistics, (2021); Bian J., Huang L., Huang X., Zhou H., Zhu S., Grantrel: Grant information extraction via joint entity and relation extraction, Proceedings of the ACL-IJCNLP, pp. 2674-2685, (2021); Bizer C., Lehmann J., Kobilarov G., Auer S., Becker C., Cyganiak R., Hellmann S., Dbpedia-a crystallization point for the web of data, Journal of Web Semantics, 7, 3, pp. 154-165, (2009); Bollacker K., Evans C., Paritosh P., Sturge T., Taylor J., Freebase: A collaboratively created graph database for structuring human knowledge, Proceedings of the 2008 ACM SIGMOD International Conference on Management of Data, pp. 1247-1250, (2008); Brown T., Mann B., Ryder N., Subbiah M., Kaplan J.D., Dhariwal P., Neelakantan A., Shyam P., Sastry G., Askell A., Language models are few-shot learners, Advances in Neural Information Processing Systems, 33, pp. 1877-1901, (2020); Cabot P.-L.H., Navigli R., REBEL: Relation extraction by end-to-end language generation, Findings of the Association for Computational Linguistics: EMNLP, pp. 2370-2381, (2021); Cai D., Lam W., Graph transformer for graph-to-sequence learning, Proceedings of the AAAI Conference on Artificial Intelligence, (2019); Cai R., Zhang X., Wang H., Bidirectional recurrent convolutional neural network for relation classification, Proceedings of the 54th Annual Meeting of the Association for Computational Linguistics (Volume 1: Long Papers), pp. 756-765, (2016); Chalkidis I., Fergadiotis M., Malakasiotis P., Aletras N., Androutsopoulos I., Legal-bert: The muppets straight out of law school, Proceedings of the EMNLP, (2020); Chan Y.S., Roth D., Exploiting syntactico-semantic structures for relation extraction, Proceedings of the 49th Annual Meeting of the Association for Computational Linguistics: Human Language Technologies, pp. 551-560, (2011); Chen H., Hong P., Han W., Majumder N., Poria S., Dialogue relation extraction with document-level heterogeneous graph attention networks, Cognitive Computation, 15, 2, pp. 793-802, (2023); Chen X., Zhang N., Li L., Deng S., Tan C., Xu C., Huang F., Si L., Chen H., Hybrid transformer with multi-level fusion for multimodal knowledge graph completion, Proceedings of the 45th International ACM SIGIR Conference on Research and Development in Information Retrieval, pp. 904-915, (2022); Chen X., Zhang N., Xie X., Deng S., Yao Y., Tan C., Huang F., Si L., Chen H., Knowprompt: Knowledge-aware prompt-tuning with synergistic optimization for relation extraction, Proceedings of the ACM Web Conference, pp. 2778-2788, (2022); Chen Y., Gantt W., Gu W., Chen T., White A.S., Van Durme B., Iterative document-level information extraction via imitation learning, Proceedings of the 17th Conference of the European Chapter of the Association for Computational Linguistics, pp. 1858-1874, (2022); Chen Y., Sun Y., Yang Z., Lin H., Joint entity and relation extraction for legal documents with legal feature enhancement, Proceedings of the International Conference on Computational Linguistics, (2020); Chen Y., Zhang Y., Hu C., Huang Y., Jointly extracting explicit and implicit relational triples with reasoning pattern enhanced binary pointer network, Proceedings of the ACL, pp. 5694-5703, (2021); Chen Y., Zhang Y., Huang Y., Learning reasoning patterns for relational triple extraction with mutual generation of text and graph, Proceedings of the ACL, pp. 1638-1647, (2022); Chen Y., Zhang Y., Huang Y., Learning reasoning patterns for relational triple extraction with mutual generation of text and graph, Findings of the Association for Computational Linguistics: ACL, (2022); Chen Z.-Y., Chang C.-H., Chen Y.-P., Nayak J., Ku L.-W., UHop: An unrestricted-hop relation extraction framework for knowledge-based question answering, Proceedings of the 2019 Conference of the North American Chapter of the Association for Computational Linguistics: Human Language Technologies, Volume, 1, pp. 345-356, (2019); Choi S.-P., Extraction of protein-protein interactions (PPIs) from the literature by deep convolutional neural networks with various feature embeddings, Journal of Information Science, 44, 1, pp. 60-73, (2018); Christopoulou F., Miwa M., Ananiadou S., Connecting the Dots: Document-level neural relation extraction with edge-oriented graphs, Proceedings of the 2019 Conference on Empirical Methods in Natural Language Processing and the 9th International Joint Conference on Natural Language Processing (EMNLP-IJCNLP), pp. 4925-4936, (2019); Christopoulou F., Miwa M., Ananiadou S., Connecting the Dots: Document-level neural relation extraction with edge-oriented graphs, Proceedings of the Conference on Empirical Methods in Natural Language Processing, (2019); Dai Q., Heinzerling B., Inui K., Cross-stitching text and knowledge graph encoders for distantly supervised relation extraction, Proceedings of the Conference on Empirical Methods in Natural Language Processing, (2022); Dai Q., Inoue N., Reisert P., Takahashi R., Inui K., Distantly supervised biomedical knowledge acquisition via knowledge graph based attention, Proceedings of the Workshop on Extracting Structured Knowledge from Scientific Publications, pp. 1-10, (2019); Cui M., Li L., Wang Z., You M., A survey on relation extraction, Knowledge Graph and Semantic Computing. Language, Knowledge, and Intelligence: Second China Conference (CCKS‚Äô17), pp. 50-58, (2017); Deusser T., Ali S.M., Hillebrand L., Nurchalifah D., Jacob B., Bauckhage C., Sifa R., KPI-EDGAR: A novel dataset and accompanying metric for relation extraction from financial documents, 21st IEEE International Conference on Machine Learning and Applications (ICMLA‚Äô22), pp. 1654-1659, (2022); Devlin J., Chang M.-W., Lee K., Toutanova K., Bert: Pre-training of deep bidirectional transformers for language understanding, Proceedings of the 2019 Conference of the North American Chapter of the Association for Computational Linguistics: Human Language Technologies, 1, pp. 4171-4186, (2018); Ding N., Wang X., Fu Y., Xu G., Wang R., Xie P., Shen Y., Huang F., Zheng H.-T., Zhang R., Prototypical representation learning for relation extraction, Proceedings of the International Conference on Learning Representations, (2020); Dixit K., Al-Onaizan Y., Span-level model for relation extraction, Proceedings of the Annual Meeting of the Association for Computational Linguistics, (2019); Doddington G.R., Mitchell A., Przybocki M., Ramshaw L., Strassel S., Weischedel R., The automatic content extraction (ACE) program‚Äìtasks, data, and evaluation, Proceedings of the Fourth International Conference on Language Resources and Evaluation (LREC‚Äô04), (2004); Dong M., Pan C., Luo Z., MapRE: An effective semantic mapping approach for low-resource relation extraction, Proceedings of the 2021 Conference on Empirical Methods in Natural Language Processing, pp. 2694-2704, (2021); Dong Q., Li L., Dai D., Zheng C., Wu Z., Chang B., Sun X., Xu J., Sui Z., A survey for in-context learning, (2022); Du J., Han J., Way A., Wan D., Multi-level structured self-attentions for distantly supervised relation extraction, Proceedings of the 2018 Conference on Empirical Methods in Natural Language Processing, pp. 2216-2225, (2018); Eberts M., Ulges A., Span-based joint entity and relation extraction with transformer pre-training, (ECAI‚Äô20), pp. 2006-2013, (2019); Eberts M., Ulges A., Span-based joint entity and relation extraction with transformer pre-training, Proceedings of the ECAI 2020, (2020); Faruqui M., Kumar S., Multilingual open relation extraction using cross-lingual projection, Proceedings of the 2015 Conference of the North American Chapter of the Association for Computational Linguistics: Human Language Technologies, pp. 1351-1356, (2015); Gao T., Fisch A., Chen D., Making pre-trained language models better few-shot learners, Proceedings of the 59th Annual Meeting of the Association for Computational Linguistics and the 11th International Joint Conference on Natural Language Processing (Volume 1: Long Papers), pp. 3816-3830, (2021); Gao T., Han X., Liu Z., Sun M., Hybrid attention-based prototypical networks for noisy few-shot relation classification, Proceedings of the AAAI Conference on Artificial Intelligence, pp. 6407-6414, (2019); Gao T., Han X., Zhu H., Liu Z., Li P., Sun M., Zhou J., FewRel 2.0: Towards more challenging few-shot relation classification, Proceedings of the EMNLP-IJCNLP, (2019); Gardent C., Shimorina A., Narayan S., Perez-Beltrachini L., Creating training corpora for nlg micro-planning, Proceedings of the 55th Annual Meeting of the Association for Computational Linguistics (ACL), (2017); Gou Y., Lei Y., Liu L., Zhang P., Peng X., A dynamic parameter enhanced network for distant supervised relation extraction, Knowledge-Based Systems, 197, (2020); Gu J., Qian L., Zhou G., Chemical-induced disease relation extraction with various linguistic features, (2016); Gu Y., Tinn R., Cheng H., Lucas M., Usuyama N., Liu X., Naumann T., Gao J., Poon H., Domain-specific language model pretraining for biomedical natural language processing, ACM Transactions on Computing for Healthcare, 3, 1, pp. 1-23, (2021); Guo Q., Yang Y., Yan H., Qiu X., Zhang Z., DORE: Document ordered relation extraction based on generative framework, Proceedings of the Conference on Empirical Methods in Natural Language Processing, (2022); Guo Z., Zhang Y., Lu W., Attention guided graph convolutional networks for relation extraction, Proceedings of the 57th Annual Meeting of the Association for Computational Linguistics, pp. 241-251, (2019); Gutierrez B.J., McNeal N., Washington C., Chen Y., Li L., Sun H., Su Y., Thinking about GPT-3 in-context learning for biomedical ie? think again, Findings of the Association for Computational Linguistics (EMNLP‚Äô22), (2022); Han J., Cheng B., Lu W., Exploring task difficulty for few-shot relation extraction, Proceedings of the 2021 Conference on Empirical Methods in Natural Language Processing, pp. 2605-2616, (2021); Han X., Gao T., Lin Y., Peng H., Yang Y., Xiao C., Liu Z., Li P., Sun M., Zhou J., More data, more relations, more context and more openness: A review and outlook for relation extraction, Proceedings of the AACL, (2020); Han X., Zhao W., Ding N., Liu Z., Sun M., Ptr: Prompt tuning with rules for text classification, AI Open, 3, pp. 182-192, (2021); Ul Haq H., Kocaman V., Talby D., Veyseh A.P.B., Dernoncourt F., Nguyen T.H., Lai V.D., Deeper clinical document understanding using relation extraction, Proceedings of the Workshop on Scientific Document Understanding, (2022); Hendrycks D., Burns C., Chen A., Ball S., Cuad: An expert-annotated nlp dataset for legal contract review, (2021); Herrero-Zazo M., Segura-Bedmar I., Martinez P., Declerck T., The DDI corpus: An annotated corpus with pharmacological substances and drug‚Äìdrug interactions, Journal of Biomedical Informatics, 46, 5, pp. 914-920, (2013); Hewlett D., Lacoste A., Jones L., Polosukhin I., Fandrianto A., Han J., Kelcey M., Berthelot D., WikiReading: A novel large-scale language understanding task over wikipedia, Proceedings of the ACL, (2016); Hillebrand L., Deusser T., Dilmaghani T., Kliem B., Loitz R., Bauckhage C., Sifa R., Kpi-bert: A joint named entity recognition and relation extraction model for financial reports, Proceedings of the 2022 26th International Conference on Pattern Recognition (ICPR), pp. 606-612, (2022); Hou Y., Jochim C., Gleize M., Bonin F., Ganguly D., Identification of tasks, datasets, evaluation metrics, and numeric scores for scientific leaderboards construction, Proceedings of the 57th Annual Meeting of the Association for Computational Linguistics, pp. 5203-5213, (2019); Hu X., Wen L., Xu Y., Zhang C., Yu Philip S., SelfORE: Self-supervised relational feature learning for open relation extraction, Proceedings of the 2020 Conference on Empirical Methods in Natural Language Processing (EMNLP), pp. 3673-3682, (2020); Huang Z., Xu W., Yu K., Bidirectional LSTM-CRF models for sequence tagging, (2015); Jabbari A.A., Sauvage O., Zeine H., Chergui H., A french corpus and annotation schema for named entity recognition and relation extraction of financial news, Proceedings of the International Conference on Language Resources and Evaluation, (2020); Jain S., van Zuylen M., Hajishirzi H., Beltagy I., SciREX: A challenge dataset for document-level information extraction, Proceedings of the 58th Annual Meeting of the Association for Computational Linguistics, pp. 7506-7516, (2020); Hu L., Zhang L., Shi C., Nie L., Guan W., Yang C., Improving distantly-supervised relation extraction with joint label embedding, Proceedings of the 2019 Conference on Empirical Methods in Natural Language Processing and the 9th International Joint Conference on Natural Language Processing, pp. 3821-3829, (2019); Ji B., Yu J., Li S., Ma J., Wu Q., Tan Y., Liu H., Span-based joint entity and relation extraction with attention-based span-specific and contextual semantic representations, Proceedings of the 28th International Conference on Computational Linguistics, pp. 88-99, (2020); Ji B., Yu J., Li S., Ma J., Wu Q., Tan Y., Liu H., Span-based Joint Entity and Relation Extraction with Attention-based Span-specific and Contextual Semantic Representations, Proceedings of the International Conference on Computational Linguistics, (2020); Jia R., Wong C., Poon H., Document-level N-ary relation extraction with multiscale representation learning, Proceedings of the ACL, (2019); Jiang P., Lin J., Wang Z., Sun J., Han J., GenRES: Rethinking evaluation for generative relation extraction in the era of large language models, Proceedings of the 2024 Conference of the North American Chapter of the Association for Computational Linguistics: Human Language Technologies (Volume 1: Long Papers), pp. 2820-2837, (2024); Jiang X., He K., He J., Yan G., A new entity extraction method based on machine reading comprehension, (2021); Jiang Z., Xu F.F., Araki J., Neubig G., How can we know what language models know?, Transactions of the Association for Computational Linguistics, 8, pp. 423-438, (2020); Joshi M., Chen D., Liu Y., Weld D.S., Zettlemoyer L., Levy O., SpanBERT: Improving pre-training by representing and predicting spans, Transactions of the Association for Computational Linguistics, 8, pp. 64-77, (2020); Kanjirangat V., Rinaldi F., Enhancing biomedical relation extraction with transformer models using shortest dependency path features and triplet information, Journal of Biomedical Informatics, 122, (2021); Kassner N., Dufter P., Schutze H., Multilingual LAMA: Investigating knowledge in multilingual pretrained language models, Proceedings of the 16th Conference of the European Chapter of the Association for Computational Linguistics: Main, pp. 3250-3258, (2021); Kruiper R., Vincent J., Chen-Burger J., Desmulliez M., Konstas I., In layman‚Äôs terms: Semi-open relation extraction from scientific texts, Proceedings of the 58th Annual Meeting of the Association for Computational Linguistics, pp. 1489-1500, (2020); Lee B., Choi Y.S., Graph based network with contextualized representations of turns in dialogue, Proceedings of the Conference on Empirical Methods in Natural Language Processing, (2021); Lee J., Yoon W., Kim S., Kim D., Kim S., So C.H., Kang J., BioBERT: A pre-trained biomedical language representation model for biomedical text mining, Bioinformatics, 36, 4, pp. 1234-1240, (2020); Lee S., Seo S., Oh B., Lee K.-H., Shin D., Lee Y., Cross-sentence N-ary relation extraction using entity link and discourse relation, Proceedings of the 29th ACM International Conference on Information and Knowledge Management, pp. 705-714, (2020); Lester B., Al-Rfou R., Constant N., The power of scale for parameter-efficient prompt tuning, Proceedings of the 2021 Conference on Empirical Methods in Natural Language Processing, pp. 3045-3059, (2021); Levy O., Seo M., Choi E., Zettlemoyer L., Zero-shot relation extraction via reading comprehension, Proceedings of the 21st Conference on Computational Natural Language Learning (CoNLL 2017), pp. 333-342, (2017); Li B., Ye W., Sheng Z., Xie R., Xi X., Zhang S., Graph enhanced dual attention network for document-level relation extraction, Proceedings of the International Conference on Computational Linguistics, (2020); Li F., Zhang M., Fu G., Ji D., A neural joint model for entity and relation extraction from biomedical text, BMC Bioinformatics, 18, 1, pp. 1-11, (2017); Li X., Luo X., Dong C., Yang D., Luan B., He Z., TDEER: An efficient translating decoding schema for joint extraction of entities and relations, Proceedings of the 2021 Conference on Empirical Methods in Natural Language Processing, pp. 8055-8064, (2021); Li X., Yin F., Sun Z., Li X., Yuan A., Chai D., Zhou M., Li J., Entity-relation extraction as multi-turn question answering, Proceedings of the 57th Annual Meeting of the Association for Computational Linguistics, pp. 1340-1350, (2019); Li X.L., Liang P., Prefix-tuning: Optimizing continuous prompts for generation, Proceedings of the 59th Annual Meeting of the Association for Computational Linguistics and the 11th International Joint Conference on Natural Language Processing (Volume 1: Long Papers), pp. 4582-4597, (2021); Li Y., Long G., Shen T., Zhou T., Yao L., Huo H., Jiang J., Self-attention enhanced selective gate with entity-aware embedding for distantly supervised relation extraction, Proceedings of the AAAI Conference on Artificial Intelligence, pp. 8269-8276, (2020); Liu W., Zhou P., Zhao Z., Wang Z., Ju Q., Deng H., Wang P., K-bert: Enabling language representation with knowledge graph, Proceedings of the AAAI Conference on Artificial Intelligence, pp. 2901-2908, (2020); Liu Y., Hu J., Wan X., Chang T.-H., Learn from relation information: Towards prototype representation rectification for few-shot relation extraction, Findings of the Association for Computational Linguistics: NAACL, pp. 1822-1831, (2022); Liu Y., Ott M., Goyal N., Du J., Joshi M., Chen D., Levy O., Lewis M., Zettlemoyer L., Stoyanov V., Roberta: A robustly optimized bert pretraining approach, (2019); Luan Y., Information extraction from scientific literature for method recommendation, (2018); Luan Y., He L., Ostendorf M., Hajishirzi H., Multi-task identification of entities, relations, and coreference for scientific knowledge graph construction, Proceedings of the 2018 Conference on Empirical Methods in Natural Language Processing, pp. 3219-3232, (2018); Luan Y., He L., Ostendorf M., Hajishirzi H., Multi-task identification of entities, relations, and coreference for scientific knowledge graph construction, Proceedings of the Conference on Empirical Methods in Natural Language Processing, (2018); Luan Y., Wadden D., He L., Shah A., Ostendorf M., Hajishirzi H., A general framework for information extraction using dynamic span graphs, Proceedings of the 2019 Conference of the North American Chapter of the Association for Computational Linguistics: Human Language Technologies, Volume, 1, pp. 3036-3046, (2019); Luo K., Lin F., Luo X., Zhu K., Knowledge base question answering via encoding of complex query graphs, Proceedings of the 2018 Conference on Empirical Methods in Natural Language Processing, pp. 2185-2194, (2018); Ma X., Hovy E., End-to-end sequence labeling via bi-directional lstm-cnns-crf, Proceedings of the 54th Annual Meeting of the Association for Computational Linguistics (Volume 1: Long Papers), pp. 1064-1074, (2016); Magnusson I.H., Friedman S.E., Extracting fine-grained knowledge graphs of scientific claims: Dataset and transformer-based results, Proceedings of the Conference on Empirical Methods in Natural Language Processing, (2021); Mandya A., Bollegala D., Coenen F., Graph convolution over multiple dependency subgraphs for relation extraction, Proceedings of the COLING. International Committee on Computational Linguistics, pp. 6424-6435, (2020); Mikolov T., Chen K., Corrado G., Dean J., Efficient estimation of word representations in vector space, (2013); Mikolov T., Sutskever I., Chen K., Corrado G.S., Dean J., Distributed representations of words and phrases and their compositionality, Advances in Neural Information Processing Systems, 26, (2013); Milosevic N., Thielemann W., Relationship extraction for knowledge graph creation from biomedical literature, (2022); Mintz M., Bills S., Snow R., Jurafsky D., Distant supervision for relation extraction without labeled data, Proceedings of the Joint Conference of the 47th Annual Meeting of the ACL and the 4th International Joint Conference on Natural Language Processing of the AFNLP, pp. 1003-1011, (2009); Miwa M., Bansal M., End-to-end relation extraction using LSTMs on sequences and tree structures, Proceedings of the ACL, (2016); Nan G., Guo Z., Sekulic I., Lu W., Reasoning with latent structure refinement for document-level relation extraction, Proceedings of the 58th Annual Meeting of the Association for Computational Linguistics, pp. 1546-1557, (2020); Nan G., Guo Z., Sekulic I., Lu W., Reasoning with latent structure refinement for document-level relation extraction, Proceedings of the Annual Meeting of the Association for Computational Linguistics, (2020); Nayak T., Majumder N., Goyal P., Poria S., Deep neural approaches to relation triplets extraction: A comprehensive survey, Cognitive Computation, 13, 5, pp. 1215-1232, (2021); Nayak T., Ng H.T., Effective modeling of encoder-decoder architecture for joint entity and relation extraction, Proceedings of the AAAI Conference on Artificial Intelligence, pp. 8528-8535, (2020); Paolini G., Athiwaratkun B., Krone J., Ma J., Achille A., Anubhai R., dos Santos C.N., Xiang B., Soatto S., Structured prediction as translation between augmented natural languages, Proceedings of the International Conference on Learning Representations, (2021); Pawar S., Palshikar G.K., Bhattacharyya P., Relation extraction: A survey, (2017); Peng Y., Yan S., Lu Z., Transfer learning in biomedical natural language processing: An evaluation of BERT and ELMo on ten benchmarking datasets, Proceedings of the 18th BioNLP Workshop and Shared Task, (2019); Pennington J., Socher R., Manning C.D., Glove: Global vectors for word representation, Proceedings of the 2014 Conference on Empirical Methods in Natural Language Processing (EMNLP), pp. 1532-1543, (2014); Peters M.E., Neumann M., Iyyer M., Gardner M., Clark C., Lee K., Zettlemoyer L., Deep contextualized word representations, Proceedings of the 2018 Conference of the North American Chapter of the Association for Computational Linguistics, pp. 2227-2237, (2018); Phi V.-T., Santoso J., Tran V.-H., Shindo H., Shimbo M., Matsumoto Y., Distant supervision for relation extraction via piecewise attention and bag-level contextual inference, IEEE Access, 7, pp. 103570-103582, (2019); Qin G., Eisner J., Learning how to ask: Querying LMs with mixtures of soft prompts, Proceedings of the 2021 Conference of the North American Chapter of the Association for Computational Linguistics: Human Language Technologies, pp. 5203-5212, (2021); Qiu L., Liang Y., Zhao Y., Lu P., Peng B., Yu Z., Wu Y.N., Zhu S.-C., SocAoG: Incremental graph parsing for social relation inference in dialogues, Proceedings of the 59th Annual Meeting of the Association for Computational Linguistics and the 11th International Joint Conference on Natural Language Processing (Volume 1: Long Papers), pp. 658-670, (2021); Qu M., Gao T., Xhonneux L.-P., Tang J., Few-shot relation extraction via bayesian meta-learning on relation graphs, International Conference on Machine Learning, pp. 7867-7876, (2020); Rathore V., Badola K., Singla P., PARE: A simple and strong baseline for monolingual and multilingual distantly supervised relation extraction, Proceedings of the 60th Annual Meeting of the Association for Computational Linguistics Volume, 2, pp. 340-354, (2022); Ren X., Wu Z., He W., Qu M., Voss C.R., Ji H., Abdelzaher T.F., Han J., Cotype: Joint extraction of typed entities and relations with knowledge bases, Proceedings of the 26th International Conference on World Wide Web, pp. 1015-1024, (2017); Ribeiro M.T., Singh S., Guestrin C., Why should i trust you?‚Äù Explaining the predictions of any classifier, Proceedings of the 22nd ACM SIGKDD International Conference on Knowledge Discovery and Data Mining, pp. 1135-1144, (2016); Riedel S., Yao L., McCallum A., Modeling relations and their mentions without labeled text, Proceedings of the Joint European Conference on Machine Learning and Knowledge Discovery in Databases, (2010); Roy A., Pan S., Incorporating medical knowledge in BERT for clinical relation extraction, Proceedings of the EMNLP, (2021); Roy A., Pan S., Incorporating medical knowledge in BERT for clinical relation extraction, Proceedings of the Conference on Empirical Methods in Natural Language Processing, (2021); Saeed W., Omlin C., Explainable AI (XAI): A systematic meta-survey of current challenges and future opportunities, Knowledge-Based Systems, 263, (2023); Sahu S.K., Christopoulou F., Miwa M., Ananiadou S., Inter-sentence relation extraction with document-level graph convolutional neural network, Proceedings of the 57th Annual Meeting of the Association for Computational Linguistics, pp. 4309-4316, (2019); Sainz O., de Lacalle O.L., Labaka G., Barrena A., Agirre E., Label verbalization and entailment for effective zero and few-shot relation extraction, Proceedings of the 2021 Conference on Empirical Methods in Natural Language Processing, pp. 1199-1212, (2021); Santosh T., Chakraborty P., Dutta S., Sanyal D.K., Das P.P., Joint entity and relation extraction from scientific documents: Role of linguistic information and entity types, EEKE@ JCDL, 21, pp. 15-19, (2021); Sarrouti M., Tao C., Randriamihaja Y.M., Comparing encoder-only and encoder-decoder transformers for relation extraction from biomedical texts: An empirical study on ten benchmark datasets, Proceedings of the BIONLP, (2022); Schick T., Schmid H., Schutze H., Automatically identifying words that can serve as labels for few-shot text classification, Proceedings of the 28th International Conference on Computational Linguistics, pp. 5569-5578, (2020); Schick T., Schutze H., Exploiting cloze-questions for few-shot text classification and natural language inference, Proceedings of the 16th Conference of the European Chapter of the Association for Computational Linguistics: Main, pp. 255-269, (2021); Seganti A., Firlag K., Skowronska H., Satlawa M., Andruszkiewicz P., Multilingual entity and relation extraction dataset and model, Proceedings of the ACL, (2021); Shang Y., Huang H.-Y., Mao X.-L., Sun X., Wei W., Are noisy sentences useless for distant supervised relation extraction?, Proceedings of the AAAI Conference on Artificial Intelligence, pp. 8799-8806, (2020); Shang Y.-M., Huang H., Sun X., Wei W., Mao X.-L., Learning relation ties with a force-directed graph in distant supervised relation extraction, ACM Transactions on Information Systems, 41, 1, pp. 1-23, (2023); Sharma S., Nayak T., Bose A., Meena A.K., Dasgupta K., Ganguly N., Goyal P., FinRED: A dataset for relation extraction in financial domain, Companion Proceedings of the Web Conference, pp. 595-597, (2022); Shen Y., Huang X.-J., Attention-based convolutional neural network for semantic relation extraction, Proceedings of COLING 2016, the 26th International Conference on Computational Linguistics: Technical Papers, pp. 2526-2536, (2016); Shen Y., Ma X., Tang Y., Lu W., A trigger-sense memory flow framework for joint entity and relation extraction, Proceedings of the Web Conference, pp. 1704-1715, (2021); Shin T., Razeghi Y., Robert L., Logan I.V., Wallace E., Singh S., AutoPrompt: Eliciting knowledge from language models with automatically generated prompts, Proceedings of the 2020 Conference on Empirical Methods in Natural Language Processing (EMNLP), pp. 4222-4235, (2020); Soares L.B., Fitzgerald N., Ling J., Kwiatkowski T., Matching the blanks: Distributional similarity for relation learning, Proceedings of the 57th Annual Meeting of the Association for Computational Linguistics, pp. 2895-2905, (2019); Socher R., Huval B., Manning C.D., Ng A.Y., Semantic compositionality through recursive matrix-vector spaces, Proceedings of the 2012 Joint Conference on Empirical Methods in Natural Language Processing and Computational Natural Language Learning, pp. 1201-1211, (2012); Son J., Kim J., Lim J.H., Lim H.-J., GRASP: Guiding model with relational semantics using prompt for dialogue relation extraction, Proceedings of the International Conference on Computational Linguistics, (2022); Song W., Zhou X., Yang P., Sun Y., Yang L., Lin H., Joint entity and relation extraction for legal texts, Proceedings of the 20th Chinese National Conference on Computational Linguistics, pp. 589-599, (2021); Subburathinam A., Lu D., Ji H., May J., Chang S.-F., Sil A., Voss C., Cross-lingual structure transfer for relation and event extraction, Proceedings of the 2019 Conference on Empirical Methods in Natural Language Processing and the 9th International Joint Conference on Natural Language Processing (EMNLP-IJCNLP), pp. 313-325, (2019); Sui D., Zeng X., Chen Y., Liu K., Zhao J., Joint entity and relation extraction with set prediction networks, IEEE Transactions on Neural Networks and Learning Systems, (2023); Sun K., Zhang R., Mensah S., Mao Y., Liu X., Recurrent interaction network for jointly extracting entities and classifying relations, Proceedings of the 2020 Conference on Empirical Methods in Natural Language Processing (EMNLP), pp. 3722-3732, (2020); Sun Q., Huang K., Yang X., Tong R., Zhang K., Poria S., Consistency guided knowledge retrieval and denoising in LLMs for zero-shot document-level relation triplet extraction, Proceedings of the ACM on Web Conference, pp. 4407-4416, (2024); Taille B., Guigue V., Scoutheeten G., Gallinari P., Let‚Äôs stop incorrect comparisons in end-to-end relation extraction!, Proceedings of the 2020 Conference on Empirical Methods in Natural Language Processing (EMNLP), pp. 3689-3701, (2020); Tan X., Pergola G., He Y., Extracting event temporal relations via hyperbolic geometry, Proceedings of the 2021 Conference on Empirical Methods in Natural Language Processing, pp. 8065-8077, (2021); Tang W., Xu B., Zhao Y., Mao Z., Liu Y., Liao Y., Xie H., UniRel: Unified representation and interaction for joint relational triple extraction, Proceedings of the 2022 Conference on Empirical Methods in Natural Language Processing, pp. 7087-7099, (2022) | AC3: X. Zhao; The Chinese University of Hong Kong, Hong Kong, Hong Kong; email: xzhao@se.cuhk.edu.hk; M. Yang; Shenzhen Institutes of Advanced Technology, Chinese Academy of Sciences, Shenzhen, Guangdong, China; email: min.yang@siat.ac.cn; Y. Shen; Sun Yat-Sen University, Shenzhen, Guangdong, China; email: sheny76@mail.sysu.edu.cn | AE3: Association for Computing Machinery | AK3: 3600300 | AM3: ACSUE | AO3: English | AP3: ACM Comput Surv | AQ3: Article | AR3: Final | AS3: All Open Access; Bronze Open Access | AT3: Scopus | AU3: 2-s2.0-85200560529 | AV3: q1 | AW3: Scopus | AX3: ? | AY3: =IF(AX3=TRUE,1,IF(AX3=FALSE,0,-1)) -> -1 | AZ3: ? | BA3: =IF(AZ3=TRUE,1,IF(AZ3=FALSE,0,-1)) -> -1 | BB3: TRUE | BC3: =IF(BB3=TRUE,1,IF(BB3=FALSE,0,-1)) -> 1 | BD3: 1 | BE3: 1 | BF3: 1 | BG3: 1 | BH3: =IF(BG3=1,"Yes",IF(BG3=-1,"Doubt","No")) -> Yes | BI3: =IF(BF3=1,"Yes","No") -> Yes | BJ3: 1 | BK3: Survey on RE. It exposes Triplet extaction also.
A4: 68 | B4: Theptakob N.; Seneewong Na Ayutthaya T.; Saetia C.; Chalothorn T.; Buabthong P. | C4: Theptakob, Nathanon (58628626400); Seneewong Na Ayutthaya, Thititorn (57209280649); Saetia, Chanatip (57204899037); Chalothorn, Tawunrat (56523303800); Buabthong, Pakpoom (57195431698) | D4: 58628626400; 57209280649; 57204899037; 56523303800; 57195431698 | E4: A Cross-Document Coreference Resolution Approach to Low-Resource Languages | F4: 2023.0 | G4: Lecture Notes in Computer Science (including subseries Lecture Notes in Artificial Intelligence and Lecture Notes in Bioinformatics) | H4: 14118 LNAI | K4: 422.0 | L4: 431.0 | M4: 9.0 | N4: 0.0 | O4: 10.1007/978-3-031-40286-9_34 | P4: https://www.scopus.com/inward/record.uri?eid=2-s2.0-85173034493&doi=10.1007%2f978-3-031-40286-9_34&partnerID=40&md5=628290bc59a106c13715816e904ac145 | Q4: Kasikorn Business-Technology Group, Nonthaburi, Thailand; Nakhon Ratchasima Rajabhat University, Nakhon Ratchasima, Thailand | R4: Theptakob N., Kasikorn Business-Technology Group, Nonthaburi, Thailand; Seneewong Na Ayutthaya T., Kasikorn Business-Technology Group, Nonthaburi, Thailand; Saetia C., Kasikorn Business-Technology Group, Nonthaburi, Thailand; Chalothorn T., Kasikorn Business-Technology Group, Nonthaburi, Thailand; Buabthong P., Kasikorn Business-Technology Group, Nonthaburi, Thailand, Nakhon Ratchasima Rajabhat University, Nakhon Ratchasima, Thailand | S4: Coreference resolution is an important area of research in natural language processing that deals with the task of identifying and grouping all the expressions in a text that refer to the same entity. This work presents a system to improve and develop a coreference resolution model for Thai language, based on the existing English clustering-based model. Specifically, we introduce a method to convert Thai text into ECB + -equivalent datasets, which can be used as benchmark for the Thai language. This paper follows an existing model trained for English coreference resolution which uses agglomerative clustering to segment clusters of coreference entities across document. The model trained and evaluated using our data achieves the best CoNLL F1 score of 72.87. Finally, we present a comparative study of the effect of manual and automatic span extractors on Thai language model performance. The results of our study indicate that our proposed pipeline, which utilizes the fine-tuned longformer model as the encoder, offers a viable alternative to more complex and resource-intensive methods. Our work also suggests that the use of existing NER and entity recognizer models can help automate span annotation prior to the subsequent conference clustering module. This study offers a potential framework for the construction of coreference resolution models in other low-resource languages. ¬© 2023, The Author(s), under exclusive license to Springer Nature Switzerland AG. | T4: Clustering; Coreference resolution; Cross-document relation extraction; Entity alignment; Knowledge graph construction | U4: Natural language processing systems; Clusterings; Coreference resolution; Cross documents; Cross-document relation extraction; Document relations; Entity alignment; Graph construction; Knowledge graph construction; Knowledge graphs; Relation extraction; Knowledge graph | AB4: Wang T., Li H., Coreference resolution improves educational knowledge graph construction, ICKG, (2020); Sukthanker R., Poria S., Cambria E., Thirunavukarasu R., Anaphora and coreference resolution: A review, Inform. Fusion, 59, pp. 139-162, (2020); Deng Y., Recommender systems based on graph embedding techniques: A review, IEEE Access, (2022); Khongcharoen W., Saetia C., Chalothorn T., Buabthong P., Question answering over knowledge graphs for thai retail banking products, Isai-Nlp. IEEE, (2022); Cattan A., Eirew A., Stanovsky G., Joshi M., Dagan I., Cross-document coreference resolution over predicted mentions, ACL, (2021); Keshtkaran A., Yuhaniz S.S., Ibrahim S., An overview of cross-document coreference resolution, Iconda, (2017); Rahimian F., Girdzijauskas S., Haridi S., Parallel community detection for cross-document coreference, IEEE WI, (2014); Culotta A., Wick M., McCallum A., First-Order Probabilistic Models for Coreference Resolution, (2007); Baron A., Freedman M., Who is who and what is what: Experiments in cross-document co-reference, EMNLP, (2008); Syed Z.S., Finin T., Joshi A., Wikitology: Using Wikipedia as an Ontology, (2008); Xue Z., Li R., Dai Q., Jiang Z., Corefdre: Document-Level Relation Extraction with Coreference Resolution, (2022); Cybulska P.V.A., Using a Sledgehammer to Crack a Nut? Lexical Diversity and Event Coreference Resolution, (2014); Moosavi N.S., Strube M., Which coreference evaluation metric do you trust? a proposal for a link-based entity aware metric, In ACL, (2016); Kongwan A., Kamaruddin S.S., Ahmad F.K., anaphora resolution in Thai EDU segmentation, J. Comput. Sci., 18, pp. 306-315, (2022); Phatthiyaphaibun W., Chaovavanich K., Polpanumas C., Suriyawongkul A., Lowphansirikul L., Chormai P., PyThaiNLP: Thai natural language processing in python, Zenodo, (2016); Klie J.-C., Bugert M., Boullosa B., de Castilho R.E., Gurevych I., The Inception Platform: Machine-Assisted and Knowledge-Oriented Interactive Annotation, (2018); Conneau A., Khandelwal K., Goyal N., Chaudhary V., Wenzek G., Guzman F., Et Al: Unsupervised Cross-Lingual Representation Learning at Scale, (2019); Lowphansirikul L., Polpanumas C., Jantrakulchai N., Nutanong S., Wangchanberta: Pretraining Transformer-Based Thai Language Models, Arxiv, 2101, (2021); Buaphet W., Udomcharoenchaikit C., Limkonchotiwat P., Rutherford A., Nutanong S., Thai nested named entity recognition corpus, ACL, (2022); Wang C., Liu X., Chen Z., Hong H., Tang J., Song D., DeepStruct: Pretraining of language models for structure prediction, ACL, (2022); Liu Y., Ott M., Goyal N., Du J., Joshi M., Chen D., Et al., Roberta: A Robustly Optimized BERT Pretraining Approach. Arxiv, 1907, (2019) | AC4: P. Buabthong; Nakhon Ratchasima Rajabhat University, Nakhon Ratchasima, Thailand; email: pakpoom.b@nrru.ac.th | AD4: Jin Z.; Jiang Y.; Ma W.; Buchmann R.A.; Ghiran A.-M.; Bi Y. | AE4: Springer Science and Business Media Deutschland GmbH | AG4: Knowledge Science, Engineering and Management - 16th International Conference, KSEM 2023, Proceedings | AH4: 16 August 2023 through 18 August 2023 | AI4: Guangzhou | AJ4: 299379.0 | AK4: 3029743 | AL4: 978-303140285-2 | AO4: English | AP4: Lect. Notes Comput. Sci. | AQ4: Conference paper | AR4: Final | AT4: Scopus | AU4: 2-s2.0-85173034493 | AV4: q1 | AW4: Scopus | AX4: TRUE | AY4: =IF(AX4=TRUE,1,IF(AX4=FALSE,0,-1)) -> 1 | AZ4: TRUE | BA4: =IF(AZ4=TRUE,1,IF(AZ4=FALSE,0,-1)) -> 1 | BB4: ? | BC4: =IF(BB4=TRUE,1,IF(BB4=FALSE,0,-1)) -> -1 | BD4: 1 | BE4: 1 | BF4: 0 | BG4: 0 | BH4: =IF(BG4=1,"Yes",IF(BG4=-1,"Doubt","No")) -> No | BI4: =IF(BF4=1,"Yes","No") -> No | BJ4: 0 | BK4: Relation clustering to perform coreference resolution applied to entities.
